Workbook

Sheet Summary>>>

Sheet GDP
A1: Country | B1: Year | C1: GDP
A2: Afghanistan | B2: 2002 | C2: =INDEX(GDP_WB_Data_202505!$E$6:$BQ$271, MATCH($A2, GDP_WB_Data_202505!$A$6:$A$271, 0 ), MATCH($B2, GDP_WB_Data_202505!$E$5:$BQ$5, 0 ) ) -> 3.8257014e+09
A3: Afghanistan | B3: 2003 | C3: =INDEX(GDP_WB_Data_202505!$E$6:$BQ$271, MATCH($A3, GDP_WB_Data_202505!$A$6:$A$271, 0 ), MATCH($B3, GDP_WB_Data_202505!$E$5:$BQ$5, 0 ) ) -> 4.5209468e+09
A4: Afghanistan | B4: 2004 | C4: =INDEX(GDP_WB_Data_202505!$E$6:$BQ$271, MATCH($A4, GDP_WB_Data_202505!$A$6:$A$271, 0 ), MATCH($B4, GDP_WB_Data_202505!$E$5:$BQ$5, 0 ) ) -> 5.2248967e+09
A5: Afghanistan | B5: 2005 | C5: =INDEX(GDP_WB_Data_202505!$E$6:$BQ$271, MATCH($A5, GDP_WB_Data_202505!$A$6:$A$271, 0 ), MATCH($B5, GDP_WB_Data_202505!$E$5:$BQ$5, 0 ) ) -> 6.2032565e+09
A6: Afghanistan | B6: 2006 | C6: =INDEX(GDP_WB_Data_202505!$E$6:$BQ$271, MATCH($A6, GDP_WB_Data_202505!$A$6:$A$271, 0 ), MATCH($B6, GDP_WB_Data_202505!$E$5:$BQ$5, 0 ) ) -> 6.9717583e+09
A7: Afghanistan | B7: 2007 | C7: =INDEX(GDP_WB_Data_202505!$E$6:$BQ$271, MATCH($A7, GDP_WB_Data_202505!$A$6:$A$271, 0 ), MATCH($B7, GDP_WB_Data_202505!$E$5:$BQ$5, 0 ) ) -> 9.7478862e+09
A8: Afghanistan | B8: 2008 | C8: =INDEX(GDP_WB_Data_202505!$E$6:$BQ$271, MATCH($A8, GDP_WB_Data_202505!$A$6:$A$271, 0 ), MATCH($B8, GDP_WB_Data_202505!$E$5:$BQ$5, 0 ) ) -> 1.0109297e+10
A9: Afghanistan | B9: 2009 | C9: =INDEX(GDP_WB_Data_202505!$E$6:$BQ$271, MATCH($A9, GDP_WB_Data_202505!$A$6:$A$271, 0 ), MATCH($B9, GDP_WB_Data_202505!$E$5:$BQ$5, 0 ) ) -> 1.2416153e+10
A10: Afghanistan | B10: 2010 | C10: =INDEX(GDP_WB_Data_202505!$E$6:$BQ$271, MATCH($A10, GDP_WB_Data_202505!$A$6:$A$271, 0 ), MATCH($B10, GDP_WB_Data_202505!$E$5:$BQ$5, 0 ) ) -> 1.5856669e+10
A11: Afghanistan | B11: 2011 | C11: =INDEX(GDP_WB_Data_202505!$E$6:$BQ$271, MATCH($A11, GDP_WB_Data_202505!$A$6:$A$271, 0 ), MATCH($B11, GDP_WB_Data_202505!$E$5:$BQ$5, 0 ) ) -> 1.7805098e+10
A12: Afghanistan | B12: 2012 | C12: =INDEX(GDP_WB_Data_202505!$E$6:$BQ$271, MATCH($A12, GDP_WB_Data_202505!$A$6:$A$271, 0 ), MATCH($B12, GDP_WB_Data_202505!$E$5:$BQ$5, 0 ) ) -> 1.990733e+10
A13: Afghanistan | B13: 2013 | C13: =INDEX(GDP_WB_Data_202505!$E$6:$BQ$271, MATCH($A13, GDP_WB_Data_202505!$A$6:$A$271, 0 ), MATCH($B13, GDP_WB_Data_202505!$E$5:$BQ$5, 0 ) ) -> 2.0146417e+10
... A943: Yemen | B943: 2024 | C943: =INDEX(GDP_WB_Data_202505!$E$6:$BQ$271, MATCH($A943, GDP_WB_Data_202505!$A$6:$A$271, 0 ), MATCH($B943, GDP_WB_Data_202505!$E$5:$BQ$5, 0 ) ) -> 18810000000

Sheet POP
A1: Country | B1: Year | C1: POP
A2: Afghanistan | B2: 2002 | C2: =INDEX(POP_WB_Data_202505!$E$6:$BQ$271, MATCH($A2, POP_WB_Data_202505!$A$6:$A$271, 0 ), MATCH($B2, POP_WB_Data_202505!$E$5:$BQ$5, 0 ) ) -> 21378117
A3: Afghanistan | B3: 2003 | C3: =INDEX(POP_WB_Data_202505!$E$6:$BQ$271, MATCH($A3, POP_WB_Data_202505!$A$6:$A$271, 0 ), MATCH($B3, POP_WB_Data_202505!$E$5:$BQ$5, 0 ) ) -> 22733049
A4: Afghanistan | B4: 2004 | C4: =INDEX(POP_WB_Data_202505!$E$6:$BQ$271, MATCH($A4, POP_WB_Data_202505!$A$6:$A$271, 0 ), MATCH($B4, POP_WB_Data_202505!$E$5:$BQ$5, 0 ) ) -> 23560654
A5: Afghanistan | B5: 2005 | C5: =INDEX(POP_WB_Data_202505!$E$6:$BQ$271, MATCH($A5, POP_WB_Data_202505!$A$6:$A$271, 0 ), MATCH($B5, POP_WB_Data_202505!$E$5:$BQ$5, 0 ) ) -> 24404567
A6: Afghanistan | B6: 2006 | C6: =INDEX(POP_WB_Data_202505!$E$6:$BQ$271, MATCH($A6, POP_WB_Data_202505!$A$6:$A$271, 0 ), MATCH($B6, POP_WB_Data_202505!$E$5:$BQ$5, 0 ) ) -> 25424094
A7: Afghanistan | B7: 2007 | C7: =INDEX(POP_WB_Data_202505!$E$6:$BQ$271, MATCH($A7, POP_WB_Data_202505!$A$6:$A$271, 0 ), MATCH($B7, POP_WB_Data_202505!$E$5:$BQ$5, 0 ) ) -> 25909852
A8: Afghanistan | B8: 2008 | C8: =INDEX(POP_WB_Data_202505!$E$6:$BQ$271, MATCH($A8, POP_WB_Data_202505!$A$6:$A$271, 0 ), MATCH($B8, POP_WB_Data_202505!$E$5:$BQ$5, 0 ) ) -> 26482622
A9: Afghanistan | B9: 2009 | C9: =INDEX(POP_WB_Data_202505!$E$6:$BQ$271, MATCH($A9, POP_WB_Data_202505!$A$6:$A$271, 0 ), MATCH($B9, POP_WB_Data_202505!$E$5:$BQ$5, 0 ) ) -> 27466101
A10: Afghanistan | B10: 2010 | C10: =INDEX(POP_WB_Data_202505!$E$6:$BQ$271, MATCH($A10, POP_WB_Data_202505!$A$6:$A$271, 0 ), MATCH($B10, POP_WB_Data_202505!$E$5:$BQ$5, 0 ) ) -> 28284089
A11: Afghanistan | B11: 2011 | C11: =INDEX(POP_WB_Data_202505!$E$6:$BQ$271, MATCH($A11, POP_WB_Data_202505!$A$6:$A$271, 0 ), MATCH($B11, POP_WB_Data_202505!$E$5:$BQ$5, 0 ) ) -> 29347708
A12: Afghanistan | B12: 2012 | C12: =INDEX(POP_WB_Data_202505!$E$6:$BQ$271, MATCH($A12, POP_WB_Data_202505!$A$6:$A$271, 0 ), MATCH($B12, POP_WB_Data_202505!$E$5:$BQ$5, 0 ) ) -> 30560034
A13: Afghanistan | B13: 2013 | C13: =INDEX(POP_WB_Data_202505!$E$6:$BQ$271, MATCH($A13, POP_WB_Data_202505!$A$6:$A$271, 0 ), MATCH($B13, POP_WB_Data_202505!$E$5:$BQ$5, 0 ) ) -> 31622704
... A943: Yemen | B943: 2024 | C943: =INDEX(POP_WB_Data_202505!$E$6:$BQ$271, MATCH($A943, POP_WB_Data_202505!$A$6:$A$271, 0 ), MATCH($B943, POP_WB_Data_202505!$E$5:$BQ$5, 0 ) ) -> 39390799

Sheet Data>>>

Sheet POP_WB_Data_202505
A5: Country Name | B5: Country Code | C5: Indicator Name | D5: Indicator Code | E5: 1960 | F5: 1961 | G5: 1962 | H5: 1963 | I5: 1964 | J5: 1965 | K5: 1966 | L5: 1967 | M5: 1968 | N5: 1969 | O5: 1970 | P5: 1971 | Q5: 1972 | R5: 1973 | S5: 1974 | T5: 1975 | U5: 1976 | V5: 1977 | W5: 1978 | X5: 1979 | Y5: 1980 | Z5: 1981 | AA5: 1982 | AB5: 1983 | AC5: 1984 | AD5: 1985 | AE5: 1986 | AF5: 1987 | AG5: 1988 | AH5: 1989 | AI5: 1990 | AJ5: 1991 | AK5: 1992 | AL5: 1993 | AM5: 1994 | AN5: 1995 | AO5: 1996 | AP5: 1997 | AQ5: 1998 | AR5: 1999 | AS5: 2000 | AT5: 2001 | AU5: 2002 | AV5: 2003 | AW5: 2004 | AX5: 2005 | AY5: 2006 | AZ5: 2007 | BA5: 2008 | BB5: 2009 | BC5: 2010 | BD5: 2011 | BE5: 2012 | BF5: 2013 | BG5: 2014 | BH5: 2015 | BI5: 2016 | BJ5: 2017 | BK5: 2018 | BL5: 2019 | BM5: 2020 | BN5: 2021 | BO5: 2022 | BP5: 2023 | BQ5: 2024
A6: Aruba | B6: ABW | C6: Population, total | D6: SP.POP.TOTL | E6: 54922 | F6: 55578 | G6: 56320 | H6: 57002 | I6: 57619 | J6: 58190 | K6: 58694 | L6: 58990 | M6: 59069 | N6: 59052 | O6: 58950 | P6: 58781 | Q6: 58047 | R6: 58299 | S6: 58349 | T6: 58295 | U6: 58368 | V6: 58580 | W6: 58776 | X6: 59191 | Y6: 59909 | Z6: 60563 | AA6: 61276 | AB6: 62228 | AC6: 62901 | AD6: 61728 | AE6: 59931 | AF6: 59159 | AG6: 59331 | AH6: 60443 | AI6: 62753 | AJ6: 65896 | AK6: 69005 | AL6: 73685 | AM6: 77595 | AN6: 79805 | AO6: 83021 | AP6: 86301 | AQ6: 88451 | AR6: 89659 | AS6: 90588 | AT6: 91439 | AU6: 92074 | AV6: 93128 | AW6: 95138 | AX6: 97635 | AY6: 99405 | AZ6: 100150 | BA6: 100917 | BB6: 101604 | BC6: 101838 | BD6: 102591 | BE6: 104110 | BF6: 105675 | BG6: 106807 | BH6: 107906 | BI6: 108727 | BJ6: 108735 | BK6: 108908 | BL6: 109203 | BM6: 108587 | BN6: 107700 | BO6: 107310 | BP6: 107359 | BQ6: =BP6 -> 107359 | BR6: =IF(ISERROR(INDEX(GDP!$A:$A, MATCH($A6, GDP!$A:$A, 0 ) )), "No", "Yes") -> No | BS6: =A6=GDP_WB_Data_202505!A6 -> TRUE
A7: Africa Eastern and Southern | B7: AFE | C7: Population, total | D7: SP.POP.TOTL | E7: 130072080 | F7: 133534923 | G7: 137171659 | H7: 140945536 | I7: 144904094 | J7: 149033472 | K7: 153281203 | L7: 157704381 | M7: 162329396 | N7: 167088245 | O7: 171984985 | P7: 177022314 | Q7: 182126556 | R7: 187524135 | S7: 193186642 | T7: 198914573 | U7: 204802976 | V7: 210680842 | W7: 217074286 | X7: 223974122 | Y7: 230792729 | Z7: 238043099 | AA7: 245822010 | AB7: 253644643 | AC7: 261458202 | AD7: 269450407 | AE7: 277621771 | AF7: 286067346 | AG7: 294498625 | AH7: 302939121 | AI7: 311748681 | AJ7: 320442961 | AK7: 329082707 | AL7: 338324002 | AM7: 347441809 | AN7: 356580375 | AO7: 366138524 | AP7: 375646235 | AQ7: 385505757 | AR7: 395750933 | AS7: 406156661 | AT7: 416807868 | AU7: 427820358 | AV7: 439173286 | AW7: 450928044 | AX7: 463076637 | AY7: 475606210 | AZ7: 488580707 | BA7: 502070763 | BB7: 516003448 | BC7: 530308387 | BD7: 544737983 | BE7: 559609961 | BF7: 575202699 | BG7: 590968990 | BH7: 607123269 | BI7: 623369401 | BJ7: 640058741 | BK7: 657801085 | BL7: 675950189 | BM7: 694446100 | BN7: 713090928 | BO7: 731821393 | BP7: 750503764 | BQ7: =BP7 -> 750503764 | BR7: =IF(ISERROR(INDEX(GDP!$A:$A, MATCH($A7, GDP!$A:$A, 0 ) )), "No", "Yes") -> No | BS7: =A7=GDP_WB_Data_202505!A7 -> TRUE
A8: Afghanistan | B8: AFG | C8: Population, total | D8: SP.POP.TOTL | E8: 9035043 | F8: 9214083 | G8: 9404406 | H8: 9604487 | I8: 9814318 | J8: 10036008 | K8: 10266395 | L8: 10505959 | M8: 10756922 | N8: 11017409 | O8: 11290128 | P8: 11567667 | Q8: 11853696 | R8: 12157999 | S8: 12469127 | T8: 12773954 | U8: 13059851 | V8: 13340756 | W8: 13611441 | X8: 13655567 | Y8: 13169311 | Z8: 11937581 | AA8: 10991378 | AB8: 10917982 | AC8: 11190221 | AD8: 11426852 | AE8: 11420074 | AF8: 11387818 | AG8: 11523298 | AH8: 11874088 | AI8: 12045660 | AJ8: 12238879 | AK8: 13278974 | AL8: 14943172 | AM8: 16250794 | AN8: 17065836 | AO8: 17763266 | AP8: 18452091 | AQ8: 19159996 | AR8: 19887785 | AS8: 20130327 | AT8: 20284307 | AU8: 21378117 | AV8: 22733049 | AW8: 23560654 | AX8: 24404567 | AY8: 25424094 | AZ8: 25909852 | BA8: 26482622 | BB8: 27466101 | BC8: 28284089 | BD8: 29347708 | BE8: 30560034 | BF8: 31622704 | BG8: 32792523 | BH8: 33831764 | BI8: 34700612 | BJ8: 35688935 | BK8: 36743039 | BL8: 37856121 | BM8: 39068979 | BN8: 40000412 | BO8: 40578842 | BP8: 41454761 | BQ8: =BP8 -> 41454761 | BR8: =IF(ISERROR(INDEX(GDP!$A:$A, MATCH($A8, GDP!$A:$A, 0 ) )), "No", "Yes") -> Yes | BS8: =A8=GDP_WB_Data_202505!A8 -> TRUE
A9: Africa Western and Central | B9: AFW | C9: Population, total | D9: SP.POP.TOTL | E9: 97630925 | F9: 99706674 | G9: 101854756 | H9: 104089175 | I9: 106388440 | J9: 108772632 | K9: 111246953 | L9: 113795019 | M9: 116444636 | N9: 119203521 | O9: 122086536 | P9: 125072948 | Q9: 128176494 | R9: 131449942 | S9: 134911581 | T9: 138569918 | U9: 142337272 | V9: 146258576 | W9: 150402616 | X9: 154721711 | Y9: 159166518 | Z9: 163762473 | AA9: 168585118 | AB9: 173255157 | AC9: 177880746 | AD9: 182811038 | AE9: 187889141 | AF9: 193104347 | AG9: 198485027 | AH9: 204062274 | AI9: 209566031 | AJ9: 215178709 | AK9: 221191375 | AL9: 227246778 | AM9: 233360104 | AN9: 239801875 | AO9: 246415446 | AP9: 253207584 | AQ9: 260297834 | AR9: 267506298 | AS9: 274968446 | AT9: 282780717 | AU9: 290841795 | AV9: 299142845 | AW9: 307725100 | AX9: 316588476 | AY9: 325663158 | AZ9: 334984176 | BA9: 344586109 | BB9: 354343844 | BC9: 364358270 | BD9: 374790143 | BE9: 385360349 | BF9: 396030207 | BG9: 406992047 | BH9: 418127845 | BI9: 429454743 | BJ9: 440882906 | BK9: 452195915 | BL9: 463365429 | BM9: 474569351 | BN9: 485920997 | BO9: 497387180 | BP9: 509398589 | BQ9: =BP9 -> 509398589 | BR9: =IF(ISERROR(INDEX(GDP!$A:$A, MATCH($A9, GDP!$A:$A, 0 ) )), "No", "Yes") -> No | BS9: =A9=GDP_WB_Data_202505!A9 -> TRUE
A10: Angola | B10: AGO | C10: Population, total | D10: SP.POP.TOTL | E10: 5231654 | F10: 5301583 | G10: 5354310 | H10: 5408320 | I10: 5464187 | J10: 5521981 | K10: 5581386 | L10: 5641807 | M10: 5702699 | N10: 5763685 | O10: 5852788 | P10: 5991102 | Q10: 6174262 | R10: 6388528 | S10: 6613367 | T10: 6842947 | U10: 7074664 | V10: 7317829 | W10: 7576734 | X10: 7847207 | Y10: 8133872 | Z10: 8435607 | AA10: 8751648 | AB10: 9082983 | AC10: 9425917 | AD10: 9779120 | AE10: 10139450 | AF10: 10497858 | AG10: 10861291 | AH10: 11238562 | AI10: 11626360 | AJ10: 12023529 | AK10: 12423712 | AL10: 12827135 | AM10: 13249764 | AN10: 13699778 | AO10: 14170973 | AP10: 14660413 | AQ10: 15159370 | AR10: 15667235 | AS10: 16194869 | AT10: 16747208 | AU10: 17327699 | AV10: 17943712 | AW10: 18600423 | AX10: 19291161 | AY10: 20015279 | AZ10: 20778561 | BA10: 21578655 | BB10: 22414773 | BC10: 23294825 | BD10: 24218352 | BE10: 25177394 | BF10: 26165620 | BG10: 27160769 | BH10: 28157798 | BI10: 29183070 | BJ10: 30234839 | BK10: 31297155 | BL10: 32375632 | BM10: 33451132 | BN10: 34532429 | BO10: 35635029 | BP10: 36749906 | BQ10: =BP10 -> 36749906 | BR10: =IF(ISERROR(INDEX(GDP!$A:$A, MATCH($A10, GDP!$A:$A, 0 ) )), "No", "Yes") -> Yes | BS10: =A10=GDP_WB_Data_202505!A10 -> TRUE
A11: Albania | B11: ALB | C11: Population, total | D11: SP.POP.TOTL | E11: 1608800 | F11: 1659800 | G11: 1711319 | H11: 1762621 | I11: 1814135 | J11: 1864791 | K11: 1914573 | L11: 1965598 | M11: 2022272 | N11: 2081695 | O11: 2135479 | P11: 2187853 | Q11: 2243126 | R11: 2296752 | S11: 2350124 | T11: 2404831 | U11: 2458526 | V11: 2513546 | W11: 2566266 | X11: 2617832 | Y11: 2671997 | Z11: 2726056 | AA11: 2784278 | AB11: 2843960 | AC11: 2904429 | AD11: 2964762 | AE11: 3022635 | AF11: 3083605 | AG11: 3142336 | AH11: 3227943 | AI11: 3286542 | AJ11: 3266790 | AK11: 3247039 | AL11: 3227287 | AM11: 3207536 | AN11: 3187784 | AO11: 3168033 | AP11: 3148281 | AQ11: 3128530 | AR11: 3108778 | AS11: 3089027 | AT11: 3060173 | AU11: 3051010 | AV11: 3039616 | AW11: 3026939 | AX11: 3011487 | AY11: 2992547 | AZ11: 2970017 | BA11: 2947314 | BB11: 2927519 | BC11: 2913021 | BD11: 2905195 | BE11: 2900401 | BF11: 2895092 | BG11: 2889104 | BH11: 2880703 | BI11: 2876101 | BJ11: 2873457 | BK11: 2866376 | BL11: 2854191 | BM11: 2837849 | BN11: 2811666 | BO11: 2777689 | BP11: 2745972 | BQ11: =BP11 -> 2745972 | BR11: =IF(ISERROR(INDEX(GDP!$A:$A, MATCH($A11, GDP!$A:$A, 0 ) )), "No", "Yes") -> No | BS11: =A11=GDP_WB_Data_202505!A11 -> TRUE
A12: Andorra | B12: AND | C12: Population, total | D12: SP.POP.TOTL | E12: 9510 | F12: 10283 | G12: 11086 | H12: 11915 | I12: 12764 | J12: 13634 | K12: 14626 | L12: 15837 | M12: 17176 | N12: 18555 | O12: 19977 | P12: 21442 | Q12: 22957 | R12: 24523 | S12: 26130 | T12: 27773 | U12: 29436 | V12: 31097 | W12: 32735 | X12: 34306 | Y12: 35782 | Z12: 37169 | AA12: 38764 | AB12: 40565 | AC12: 42273 | AD12: 43825 | AE12: 45734 | AF12: 47653 | AG12: 49416 | AH12: 50620 | AI12: 52597 | AJ12: 56667 | AK12: 60200 | AL12: 63272 | AM12: 64612 | AN12: 63912 | AO12: 63984 | AP12: 64700 | AQ12: 65382 | AR12: 65710 | AS12: 65685 | AT12: 65852 | AU12: 66506 | AV12: 69486 | AW12: 74325 | AX12: 77421 | AY12: 79585 | AZ12: 81877 | BA12: 83495 | BB12: 83888 | BC12: 80706 | BD12: 77783 | BE12: 76834 | BF12: 75194 | BG12: 73737 | BH12: 72174 | BI12: 72181 | BJ12: 73763 | BK12: 75162 | BL12: 76474 | BM12: 77380 | BN12: 78364 | BO12: 79705 | BP12: 80856 | BQ12: =BP12 -> 80856 | BR12: =IF(ISERROR(INDEX(GDP!$A:$A, MATCH($A12, GDP!$A:$A, 0 ) )), "No", "Yes") -> No | BS12: =A12=GDP_WB_Data_202505!A12 -> TRUE
A13: Arab World | B13: ARB | C13: Population, total | D13: SP.POP.TOTL | E13: 91540853 | F13: 93931683 | G13: 96428599 | H13: 99038509 | I13: 101729760 | J13: 104494008 | K13: 107403055 | L13: 110491709 | M13: 113712171 | N13: 117053219 | O13: 120469263 | P13: 123950810 | Q13: 127535560 | R13: 131335660 | S13: 135282861 | T13: 139495837 | U13: 144014135 | V13: 148599336 | W13: 153568663 | X13: 159054118 | Y13: 164657321 | Z13: 170015485 | AA13: 175370356 | AB13: 180973288 | AC13: 186733957 | AD13: 192563243 | AE13: 198509771 | AF13: 204524595 | AG13: 210269696 | AH13: 215969068 | AI13: 223184294 | AJ13: 228402316 | AK13: 234321565 | AL13: 240926205 | AM13: 247626514 | AN13: 253952538 | AO13: 260229121 | AP13: 266565183 | AQ13: 273094199 | AR13: 279709634 | AS13: 286548096 | AT13: 293580252 | AU13: 300691509 | AV13: 307815105 | AW13: 315060277 | AX13: 322628451 | AY13: 330526310 | AZ13: 338947976 | BA13: 347684619 | BB13: 356386673 | BC13: 363568534 | BD13: 372054934 | BE13: 381030177 | BF13: 390954281 | BG13: 400231008 | BH13: 410190679 | BI13: 419808341 | BJ13: 428315886 | BK13: 435998060 | BL13: 444281315 | BM13: 453723239 | BN13: 460646603 | BO13: 471352066 | BP13: 481667539 | BQ13: =BP13 -> 481667539 | BR13: =IF(ISERROR(INDEX(GDP!$A:$A, MATCH($A13, GDP!$A:$A, 0 ) )), "No", "Yes") -> No | BS13: =A13=GDP_WB_Data_202505!A13 -> TRUE
A14: United Arab Emirates | B14: ARE | C14: Population, total | D14: SP.POP.TOTL | E14: 131334 | F14: 137989 | G14: 144946 | H14: 152211 | I14: 159692 | J14: 167103 | K14: 173976 | L14: 179700 | M14: 199416 | N14: 239660 | O14: 286536 | P14: 335027 | Q14: 385014 | R14: 436399 | S14: 489087 | T14: 542856 | U14: 615866 | V14: 710209 | W14: 809274 | X14: 912010 | Y14: 1015700 | Z14: 1099855 | AA14: 1166370 | AB14: 1235305 | AC14: 1305996 | AD14: 1377911 | AE14: 1467383 | AF14: 1574244 | AG14: 1681788 | AH14: 1789851 | AI14: 1898220 | AJ14: 2006626 | AK14: 2114730 | AL14: 2222093 | AM14: 2328188 | AN14: 2434662 | AO14: 2597564 | AP14: 2817410 | AQ14: 3040421 | AR14: 3266009 | AS14: 3493575 | AT14: 3723590 | AU14: 3956826 | AV14: 4192457 | AW14: 4428967 | AX14: 4664790 | AY14: 5009100 | AZ14: 5624635 | BA14: 6302664 | BB14: 6707058 | BC14: 6869838 | BD14: 7104538 | BE14: 7391448 | BF14: 7693031 | BG14: 8059440 | BH14: 8505237 | BI14: 8935095 | BJ14: 9223225 | BK14: 9346701 | BL14: 9445785 | BM14: 9401038 | BN14: 9575152 | BO14: 10074977 | BP14: 10483751 | BQ14: =BP14 -> 10483751 | BR14: =IF(ISERROR(INDEX(GDP!$A:$A, MATCH($A14, GDP!$A:$A, 0 ) )), "No", "Yes") -> No | BS14: =A14=GDP_WB_Data_202505!A14 -> TRUE
A15: Argentina | B15: ARG | C15: Population, total | D15: SP.POP.TOTL | E15: 20386045 | F15: 20726276 | G15: 21072538 | H15: 21421705 | I15: 21769453 | J15: 22112629 | K15: 22453893 | L15: 22799059 | M15: 23150583 | N15: 23508711 | O15: 23878327 | P15: 24257208 | Q15: 24644328 | R15: 25046005 | S15: 25461351 | T15: 25874107 | U15: 26282283 | V15: 26701805 | W15: 27132158 | X15: 27568895 | Y15: 28011596 | Z15: 28463959 | AA15: 28924262 | AB15: 29391332 | AC15: 29863093 | AD15: 30336441 | AE15: 30811980 | AF15: 31291762 | AG15: 31780532 | AH15: 32270948 | AI15: 32755901 | AJ15: 33230294 | AK15: 33693527 | AL15: 34152717 | AM15: 34613491 | AN15: 35070020 | AO15: 35513793 | AP15: 35947791 | AQ15: 36372860 | AR15: 36794682 | AS15: 37213984 | AT15: 37624825 | AU15: 38029349 | AV15: 38424282 | AW15: 38815916 | AX15: 39216789 | AY15: 39622115 | AZ15: 40016763 | BA15: 40424148 | BB15: 40854831 | BC15: 41288694 | BD15: 41730660 | BE15: 42161721 | BF15: 42582455 | BG15: 43024071 | BH15: 43477012 | BI15: 43900313 | BJ15: 44288894 | BK15: 44654882 | BL15: 44973465 | BM15: 45191965 | BN15: 45312281 | BO15: 45407904 | BP15: 45538401 | BQ15: =BP15 -> 45538401 | BR15: =IF(ISERROR(INDEX(GDP!$A:$A, MATCH($A15, GDP!$A:$A, 0 ) )), "No", "Yes") -> No | BS15: =A15=GDP_WB_Data_202505!A15 -> TRUE
A16: Armenia | B16: ARM | C16: Population, total | D16: SP.POP.TOTL | E16: 1863705 | F16: 1927484 | G16: 1991689 | H16: 2056023 | I16: 2120135 | J16: 2183635 | K16: 2246159 | L16: 2307492 | M16: 2367319 | N16: 2424030 | O16: 2475633 | P16: 2525345 | Q16: 2577079 | R16: 2630860 | S16: 2686445 | T16: 2743660 | U16: 2818165 | V16: 2912827 | W16: 3012807 | X16: 3078501 | Y16: 3107415 | Z16: 3135349 | AA16: 3163144 | AB16: 3191539 | AC16: 3224547 | AD16: 3260432 | AE16: 3294847 | AF16: 3328520 | AG16: 3355125 | AH16: 3443100 | AI16: 3552128 | AJ16: 3613977 | AK16: 3571861 | AL16: 3453332 | AM16: 3364610 | AN16: 3307581 | AO16: 3278735 | AP16: 3246289 | AQ16: 3208401 | AR16: 3167286 | AS16: 3221100 | AT16: 3211800 | AU16: 3199800 | AV16: 3182500 | AW16: 3164900 | AX16: 3146400 | AY16: 3127100 | AZ16: 3107400 | BA16: 3087100 | BB16: 3066000 | BC16: 3044800 | BD16: 3027900 | BE16: 3024100 | BF16: 3022000 | BG16: 3013800 | BH16: 3004600 | BI16: 2992300 | BJ16: 2979400 | BK16: 2969000 | BL16: 2962500 | BM16: 2961500 | BN16: 2962300 | BO16: 2969200 | BP16: 2990900 | BQ16: =BP16 -> 2990900 | BR16: =IF(ISERROR(INDEX(GDP!$A:$A, MATCH($A16, GDP!$A:$A, 0 ) )), "No", "Yes") -> No | BS16: =A16=GDP_WB_Data_202505!A16 -> TRUE
A17: American Samoa | B17: ASM | C17: Population, total | D17: SP.POP.TOTL | E17: 20133 | F17: 20666 | G17: 21298 | H17: 21966 | I17: 22673 | J17: 23406 | K17: 24136 | L17: 24863 | M17: 25614 | N17: 26375 | O17: 27026 | P17: 27533 | Q17: 27995 | R17: 28436 | S17: 28875 | T17: 29390 | U17: 29959 | V17: 30521 | W17: 31076 | X17: 31611 | Y17: 32403 | Z17: 33584 | AA17: 34909 | AB17: 36271 | AC17: 37667 | AD17: 39103 | AE17: 40571 | AF17: 42072 | AG17: 43615 | AH17: 45191 | AI17: 46640 | AJ17: 47882 | AK17: 49038 | AL17: 50159 | AM17: 51251 | AN17: 52316 | AO17: 53353 | AP17: 54362 | AQ17: 55334 | AR17: 56248 | AS17: 56855 | AT17: 57053 | AU17: 57062 | AV17: 56971 | AW17: 56818 | AX17: 56617 | AY17: 56374 | AZ17: 56113 | BA17: 55828 | BB17: 55528 | BC17: 55228 | BD17: 54895 | BE17: 54489 | BF17: 54006 | BG17: 53466 | BH17: 52878 | BI17: 52245 | BJ17: 51586 | BK17: 50908 | BL17: 50209 | BM17: 49761 | BN17: 49225 | BO17: 48342 | BP17: 47521 | BQ17: =BP17 -> 47521 | BR17: =IF(ISERROR(INDEX(GDP!$A:$A, MATCH($A17, GDP!$A:$A, 0 ) )), "No", "Yes") -> No | BS17: =A17=GDP_WB_Data_202505!A17 -> TRUE
... A115: India | B115: IND | C115: Population, total | D115: SP.POP.TOTL | E115: 435990338 | F115: 446564729 | G115: 457283090 | H115: 468138575 | I115: 479229598 | J115: 490140146 | K115: 500740247 | L115: 511606372 | M115: 522716889 | N115: 533880544 | O115: 545864268 | P115: 558096387 | Q115: 570482142 | R115: 583465598 | S115: 597041391 | T115: 611309535 | U115: 625861883 | V115: 640801103 | W115: 655728229 | X115: 671155747 | Y115: 687354025 | Z115: 703696250 | AA115: 720313473 | AB115: 737372681 | AC115: 754875449 | AD115: 772647793 | AE115: 790689978 | AF115: 808931270 | AG115: 827342990 | AH115: 846039529 | AI115: 864972221 | AJ115: 883927600 | AK115: 902957070 | AL115: 922118387 | AM115: 941163767 | AN115: 960301044 | AO115: 979678458 | AP115: 999133762 | AQ115: 1018665080 | AR115: 1038225823 | AS115: 1057922733 | AT115: 1077898575 | AU115: 1097600380 | AV115: 1116803006 | AW115: 1135991513 | AX115: 1154676322 | AY115: 1172878890 | AZ115: 1190676021 | BA115: 1207930964 | BB115: 1225524753 | BC115: 1243481564 | BD115: 1261224954 | BE115: 1278674502 | BF115: 1295829511 | BG115: 1312277191 | BH115: 1328024498 | BI115: 1343944296 | BJ115: 1359657400 | BK115: 1374659064 | BL115: 1389030312 | BM115: 1402617695 | BN115: 1414203896 | BO115: 1425423212 | BP115: 1438069596 | BQ115: =BP115 -> 1438069596 | BR115: =IF(ISERROR(INDEX(GDP!$A:$A, MATCH($A115, GDP!$A:$A, 0 ) )), "No", "Yes") -> Yes | BS115: =A115=GDP_WB_Data_202505!A115 -> TRUE
A116: Not classified | B116: INX | C116: Population, total | D116: SP.POP.TOTL | BQ116: =BP116 -> 0 | BR116: =IF(ISERROR(INDEX(GDP!$A:$A, MATCH($A116, GDP!$A:$A, 0 ) )), "No", "Yes") -> No | BS116: =A116=GDP_WB_Data_202505!A116 -> TRUE
A117: Ireland | B117: IRL | C117: Population, total | D117: SP.POP.TOTL | E117: 2828600 | F117: 2824400 | G117: 2836050 | H117: 2852650 | I117: 2866550 | J117: 2877300 | K117: 2888800 | L117: 2902450 | M117: 2915550 | N117: 2932650 | O117: 2957250 | P117: 2992050 | Q117: 3036850 | R117: 3085950 | S117: 3137500 | T117: 3189550 | U117: 3238050 | V117: 3282200 | W117: 3329100 | X117: 3373750 | Y117: 3412800 | Z117: 3453000 | AA117: 3485800 | AB117: 3510600 | AC117: 3532423 | AD117: 3538082 | AE117: 3539690 | AF117: 3540057 | AG117: 3524949 | AH117: 3511009 | AI117: 3513974 | AJ117: 3534235 | AK117: 3558430 | AL117: 3576261 | AM117: 3590386 | AN117: 3608841 | AO117: 3637510 | AP117: 3674171 | AQ117: 3712696 | AR117: 3754786 | AS117: 3805174 | AT117: 3866243 | AU117: 3931947 | AV117: 3996521 | AW117: 4070262 | AX117: 4159914 | AY117: 4273591 | AZ117: 4398942 | BA117: 4489544 | BB117: 4535375 | BC117: 4560155 | BD117: 4580084 | BE117: 4599533 | BF117: 4623816 | BG117: 4657740 | BH117: 4701957 | BI117: 4755335 | BJ117: 4807388 | BK117: 4867316 | BL117: 4934340 | BM117: 4985382 | BN117: 5033164 | BO117: 5165700 | BP117: 5307600 | BQ117: =BP117 -> 5307600 | BR117: =IF(ISERROR(INDEX(GDP!$A:$A, MATCH($A117, GDP!$A:$A, 0 ) )), "No", "Yes") -> No | BS117: =A117=GDP_WB_Data_202505!A117 -> TRUE
A118: Iran (Islamic Republic Of) | B118: IRN | C118: Population, total | D118: SP.POP.TOTL | E118: 21470434 | F118: 22125726 | G118: 22807907 | H118: 23519005 | I118: 24262859 | J118: 25036978 | K118: 25829270 | L118: 26628432 | M118: 27437391 | N118: 28273482 | O118: 29145100 | P118: 30029071 | Q118: 30921179 | R118: 31839838 | S118: 32796463 | T118: 33802973 | U118: 34837271 | V118: 35933181 | W118: 37126535 | X118: 38424952 | Y118: 39842324 | Z118: 41989312 | AA118: 44272141 | AB118: 46029535 | AC118: 47793998 | AD118: 49582289 | AE118: 51446045 | AF118: 53323493 | AG118: 55072694 | AH118: 56704914 | AI118: 58380092 | AJ118: 59986931 | AK118: 61184983 | AL118: 61403543 | AM118: 61520598 | AN118: 62205567 | AO118: 62881300 | AP118: 63639638 | AQ118: 64519859 | AR118: 65445391 | AS118: 66418659 | AT118: 67452005 | AU118: 68011317 | AV118: 68769340 | AW118: 70256316 | AX118: 71828455 | AY118: 73392747 | AZ118: 74602648 | BA118: 75514204 | BB118: 76457825 | BC118: 77420842 | BD118: 78383598 | BE118: 79370580 | BF118: 80414686 | BG118: 81502045 | BH118: 82619362 | BI118: 83812228 | BJ118: 85026754 | BK118: 86117998 | BL118: 87051648 | BM118: 87723443 | BN118: 88455488 | BO118: 89524246 | BP118: 90608707 | BQ118: =BP118 -> 90608707 | BR118: =IF(ISERROR(INDEX(GDP!$A:$A, MATCH($A118, GDP!$A:$A, 0 ) )), "No", "Yes") -> Yes | BS118: =A118=GDP_WB_Data_202505!A118 -> TRUE
A119: Iraq | B119: IRQ | C119: Population, total | D119: SP.POP.TOTL | E119: 7022052 | F119: 7194553 | G119: 7413875 | H119: 7667928 | I119: 7929566 | J119: 8202140 | K119: 8485104 | L119: 8778869 | M119: 9085016 | N119: 9403356 | O119: 9735611 | P119: 10077809 | Q119: 10430164 | R119: 10795869 | S119: 11167761 | T119: 11543639 | U119: 11927651 | V119: 12331046 | W119: 12753355 | X119: 13170365 | Y119: 13591992 | Z119: 14006381 | AA119: 14406083 | AB119: 14840555 | AC119: 15310733 | AD119: 15683430 | AE119: 16074145 | AF119: 16521049 | AG119: 16908819 | AH119: 17364542 | AI119: 17581206 | AJ119: 17767253 | AK119: 18300845 | AL119: 19201195 | AM119: 20139807 | AN119: 20825860 | AO119: 21501321 | AP119: 22176593 | AQ119: 22884399 | AR119: 23636527 | AS119: 24424056 | AT119: 25197840 | AU119: 26006559 | AV119: 26802659 | AW119: 27577878 | AX119: 28407448 | AY119: 28616515 | AZ119: 28391607 | BA119: 28971036 | BB119: 30058206 | BC119: 31045366 | BD119: 32161424 | BE119: 33654842 | BF119: 35281989 | BG119: 36550059 | BH119: 37560535 | BI119: 38469627 | BJ119: 39337353 | BK119: 40265624 | BL119: 41192171 | BM119: 42116605 | BN119: 43071211 | BO119: 44070551 | BP119: 45074049 | BQ119: =BP119 -> 45074049 | BR119: =IF(ISERROR(INDEX(GDP!$A:$A, MATCH($A119, GDP!$A:$A, 0 ) )), "No", "Yes") -> No | BS119: =A119=GDP_WB_Data_202505!A119 -> TRUE
A120: Iceland | B120: ISL | C120: Population, total | D120: SP.POP.TOTL | E120: 175574 | F120: 179029 | G120: 182378 | H120: 185653 | I120: 188983 | J120: 192286 | K120: 195570 | L120: 198751 | M120: 201488 | N120: 203369 | O120: 204438 | P120: 206098 | Q120: 209137 | R120: 212317 | S120: 215209 | T120: 217979 | U120: 220154 | V120: 221799 | W120: 223537 | X120: 225735 | Y120: 228138 | Z120: 230755 | AA120: 233860 | AB120: 236977 | AC120: 239511 | AD120: 241405 | AE120: 243180 | AF120: 245859 | AG120: 249740 | AH120: 252852 | AI120: 254826 | AJ120: 257797 | AK120: 261057 | AL120: 263725 | AM120: 266021 | AN120: 267468 | AO120: 268916 | AP120: 271128 | AQ120: 274047 | AR120: 277381 | AS120: 281205 | AT120: 284968 | AU120: 287523 | AV120: 289521 | AW120: 292074 | AX120: 296734 | AY120: 303782 | AZ120: 311566 | BA120: 317414 | BB120: 318499 | BC120: 318041 | BD120: 319014 | BE120: 320716 | BF120: 323764 | BG120: 327386 | BH120: 330815 | BI120: 335439 | BJ120: 343400 | BK120: 352721 | BL120: 360563 | BM120: 366463 | BN120: 372520 | BO120: 382003 | BP120: 393349 | BQ120: =BP120 -> 393349 | BR120: =IF(ISERROR(INDEX(GDP!$A:$A, MATCH($A120, GDP!$A:$A, 0 ) )), "No", "Yes") -> No | BS120: =A120=GDP_WB_Data_202505!A120 -> TRUE
A121: Israel | B121: ISR | C121: Population, total | D121: SP.POP.TOTL | E121: 2114020 | F121: 2185000 | G121: 2293000 | H121: 2379000 | I121: 2475000 | J121: 2563000 | K121: 2629000 | L121: 2745000 | M121: 2803000 | N121: 2877000 | O121: 2974000 | P121: 3069000 | Q121: 3148000 | R121: 3278000 | S121: 3377000 | T121: 3455000 | U121: 3533000 | V121: 3613000 | W121: 3690000 | X121: 3786000 | Y121: 3878000 | Z121: 3956000 | AA121: 4031000 | AB121: 4105000 | AC121: 4159000 | AD121: 4233000 | AE121: 4299000 | AF121: 4369000 | AG121: 4442000 | AH121: 4518000 | AI121: 4660000 | AJ121: 4949000 | AK121: 5123000 | AL121: 5261000 | AM121: 5399000 | AN121: 5545000 | AO121: 5692000 | AP121: 5836000 | AQ121: 5971000 | AR121: 6125000 | AS121: 6289000 | AT121: 6439000 | AU121: 6570000 | AV121: 6689700 | AW121: 6809000 | AX121: 6930100 | AY121: 7053700 | AZ121: 7180100 | BA121: 7308800 | BB121: 7485600 | BC121: 7623600 | BD121: 7765800 | BE121: 7910500 | BF121: 8059500 | BG121: 8215700 | BH121: 8380100 | BI121: 8546000 | BJ121: 8713300 | BK121: 8882800 | BL121: 9054000 | BM121: 9215100 | BN121: 9371400 | BO121: 9557500 | BP121: 9756600 | BQ121: =BP121 -> 9756600 | BR121: =IF(ISERROR(INDEX(GDP!$A:$A, MATCH($A121, GDP!$A:$A, 0 ) )), "No", "Yes") -> No | BS121: =A121=GDP_WB_Data_202505!A121 -> TRUE
A122: Italy | B122: ITA | C122: Population, total | D122: SP.POP.TOTL | E122: 50199700 | F122: 50536350 | G122: 50879450 | H122: 51252000 | I122: 51675350 | J122: 52112350 | K122: 52519000 | L122: 52900500 | M122: 53235750 | N122: 53537950 | O122: 53821850 | P122: 54073490 | Q122: 54381345 | R122: 54751406 | S122: 55110868 | T122: 55441001 | U122: 55718260 | V122: 55955411 | W122: 56155143 | X122: 56317749 | Y122: 56433883 | Z122: 56501675 | AA122: 56543548 | AB122: 56564074 | AC122: 56576718 | AD122: 56593071 | AE122: 56596155 | AF122: 56601931 | AG122: 56629288 | AH122: 56671781 | AI122: 56719240 | AJ122: 56758521 | AK122: 56797087 | AL122: 56831821 | AM122: 56843400 | AN122: 56844303 | AO122: 56860281 | AP122: 56890372 | AQ122: 56906744 | AR122: 56916317 | AS122: 56942108 | AT122: 56974100 | AU122: 57059007 | AV122: 57313203 | AW122: 57685327 | AX122: 57969484 | AY122: 58143979 | AZ122: 58438310 | BA122: 58826731 | BB122: 59095365 | BC122: 59277417 | BD122: 59379449 | BE122: 59539717 | BF122: 60233948 | BG122: 60789140 | BH122: 60730582 | BI122: 60627498 | BJ122: 60536709 | BK122: 60421760 | BL122: 59729081 | BM122: 59438851 | BN122: 59133173 | BO122: 59013667 | BP122: 58993475 | BQ122: =BP122 -> 58993475 | BR122: =IF(ISERROR(INDEX(GDP!$A:$A, MATCH($A122, GDP!$A:$A, 0 ) )), "No", "Yes") -> No | BS122: =A122=GDP_WB_Data_202505!A122 -> TRUE
A123: Jamaica | B123: JAM | C123: Population, total | D123: SP.POP.TOTL | E123: 1650005 | F123: 1673261 | G123: 1696932 | H123: 1721099 | I123: 1745568 | J123: 1769192 | K123: 1791475 | L123: 1812865 | M123: 1833765 | N123: 1855127 | O123: 1878196 | P123: 1903728 | Q123: 1931542 | R123: 1961219 | S123: 1990906 | T123: 2018981 | U123: 2045578 | V123: 2070657 | W123: 2094836 | X123: 2119486 | Y123: 2145658 | Z123: 2173818 | AA123: 2203889 | AB123: 2234832 | AC123: 2264562 | AD123: 2290656 | AE123: 2312125 | AF123: 2329813 | AG123: 2345777 | AH123: 2361916 | AI123: 2379877 | AJ123: 2400869 | AK123: 2424701 | AL123: 2449916 | AM123: 2475220 | AN123: 2500151 | AO123: 2524463 | AP123: 2547848 | AQ123: 2569736 | AR123: 2589795 | AS123: 2607826 | AT123: 2624403 | AU123: 2640572 | AV123: 2656623 | AW123: 2672225 | AX123: 2687066 | AY123: 2700968 | AZ123: 2713800 | BA123: 2725635 | BB123: 2736995 | BC123: 2748568 | BD123: 2760494 | BE123: 2772430 | BF123: 2783687 | BG123: 2793749 | BH123: 2802534 | BI123: 2809915 | BJ123: 2815764 | BK123: 2820097 | BL123: 2823271 | BM123: 2830739 | BN123: 2837682 | BO123: 2839144 | BP123: 2839786 | BQ123: =BP123 -> 2839786 | BR123: =IF(ISERROR(INDEX(GDP!$A:$A, MATCH($A123, GDP!$A:$A, 0 ) )), "No", "Yes") -> Yes | BS123: =A123=GDP_WB_Data_202505!A123 -> TRUE
A124: Jordan | B124: JOR | C124: Population, total | D124: SP.POP.TOTL | E124: 853471 | F124: 897591 | G124: 940554 | H124: 984714 | I124: 1035640 | J124: 1099440 | K124: 1178360 | L124: 1271183 | M124: 1372460 | N124: 1473100 | O124: 1565163 | P124: 1645145 | Q124: 1714555 | R124: 1778094 | S124: 1839182 | T124: 1899055 | U124: 1958177 | V124: 2019002 | W124: 2083595 | X124: 2153882 | Y124: 2234186 | Z124: 2325517 | AA124: 2426927 | AB124: 2537307 | AC124: 2654688 | AD124: 2778810 | AE124: 2909887 | AF124: 3047634 | AG124: 3193039 | AH124: 3349627 | AI124: 3621908 | AJ124: 3915149 | AK124: 4127693 | AL124: 4348020 | AM124: 4561406 | AN124: 4752096 | AO124: 4912516 | AP124: 5046285 | AQ124: 5164284 | AR124: 5276444 | AS124: 5386945 | AT124: 5498894 | AU124: 5616066 | AV124: 5741828 | AW124: 5882061 | AX124: 6029587 | AY124: 6427371 | AZ124: 6827227 | BA124: 6989866 | BB124: 7141753 | BC124: 7297043 | BD124: 7480424 | BE124: 7587127 | BF124: 7991809 | BG124: 8791710 | BH124: 9544729 | BI124: 10006367 | BJ124: 10234226 | BK124: 10462306 | BL124: 10671891 | BM124: 10865228 | BN124: 11066356 | BO124: 11256263 | BP124: 11439213 | BQ124: =BP124 -> 11439213 | BR124: =IF(ISERROR(INDEX(GDP!$A:$A, MATCH($A124, GDP!$A:$A, 0 ) )), "No", "Yes") -> No | BS124: =A124=GDP_WB_Data_202505!A124 -> TRUE
A125: Japan | B125: JPN | C125: Population, total | D125: SP.POP.TOTL | E125: 93216000 | F125: 94055000 | G125: 94933000 | H125: 95900000 | I125: 96903000 | J125: 97952000 | K125: 98851000 | L125: 99879000 | M125: 101011000 | N125: 102219000 | O125: 103403000 | P125: 105697000 | Q125: 107188000 | R125: 108707000 | S125: 110162000 | T125: 111573000 | U125: 112775000 | V125: 113872000 | W125: 114913000 | X125: 115890000 | Y125: 116807000 | Z125: 117661000 | AA125: 118480000 | AB125: 119307000 | AC125: 120083000 | AD125: 120837000 | AE125: 121482000 | AF125: 122069000 | AG125: 122578000 | AH125: 123069000 | AI125: 123478000 | AJ125: 123964000 | AK125: 124425000 | AL125: 124829000 | AM125: 125178000 | AN125: 125472000 | AO125: 125757000 | AP125: 126057000 | AQ125: 126400000 | AR125: 126631000 | AS125: 126843000 | AT125: 127149000 | AU125: 127445000 | AV125: 127718000 | AW125: 127761000 | AX125: 127773000 | AY125: 127854000 | AZ125: 128001000 | BA125: 128063000 | BB125: 128047000 | BC125: 128070000 | BD125: 127833000 | BE125: 127629000 | BF125: 127445000 | BG125: 127276000 | BH125: 127141000 | BI125: 127076000 | BJ125: 126972000 | BK125: 126811000 | BL125: 126633000 | BM125: 126261000 | BN125: 125681593 | BO125: 125124989 | BP125: 124516650 | BQ125: =BP125 -> 124516650 | BR125: =IF(ISERROR(INDEX(GDP!$A:$A, MATCH($A125, GDP!$A:$A, 0 ) )), "No", "Yes") -> No | BS125: =A125=GDP_WB_Data_202505!A125 -> TRUE
A126: Kazakhstan | B126: KAZ | C126: Population, total | D126: SP.POP.TOTL | E126: 9429981 | F126: 9742085 | G126: 10058928 | H126: 10377466 | I126: 10690309 | J126: 10993183 | K126: 11288989 | L126: 11584428 | M126: 11879182 | N126: 12156212 | O126: 12419057 | P126: 12684813 | Q126: 12951798 | R126: 13208121 | S126: 13454570 | T126: 13700843 | U126: 13998738 | V126: 14353265 | W126: 14711497 | X126: 14978696 | Y126: 15152949 | Z126: 15323082 | AA126: 15492595 | AB126: 15665551 | AC126: 15844621 | AD126: 16031090 | AE126: 16262702 | AF126: 16527715 | AG126: 16781168 | AH126: 16997013 | AI126: 17154054 | AJ126: 17278600 | AK126: 17332625 | AL126: 17274487 | AM126: 17043771 | AN126: 16730536 | AO126: 16416027 | AP126: 16043251 | AQ126: 15647785 | AR126: 15455874 | AS126: 15501103 | AT126: 15575550 | AU126: 15656677 | AV126: 15747380 | AW126: 15850159 | AX126: 15968117 | AY126: 16103716 | AZ126: 16257214 | BA126: 16426525 | BB126: 16619846 | BC126: 16836810 | BD126: 17066002 | BE126: 17306106 | BF126: 17556502 | BG126: 17816285 | BH126: 18084169 | BI126: 18363600 | BJ126: 18651931 | BK126: 18932727 | BL126: 19209555 | BM126: 19482117 | BN126: 19743603 | BO126: 20034609 | BP126: 20330104 | BQ126: =BP126 -> 20330104 | BR126: =IF(ISERROR(INDEX(GDP!$A:$A, MATCH($A126, GDP!$A:$A, 0 ) )), "No", "Yes") -> No | BS126: =A126=GDP_WB_Data_202505!A126 -> TRUE
A127: Kenya | B127: KEN | C127: Population, total | D127: SP.POP.TOTL | E127: 7695307 | F127: 7987770 | G127: 8299308 | H127: 8627971 | I127: 8973535 | J127: 9338078 | K127: 9717816 | L127: 10111057 | M127: 10518823 | N127: 10939695 | O127: 11368791 | P127: 11788904 | Q127: 12206060 | R127: 12634835 | S127: 13070078 | T127: 13511671 | U127: 13957623 | V127: 14428819 | W127: 14934126 | X127: 15460666 | Y127: 16018459 | Z127: 16601507 | AA127: 17206175 | AB127: 17846374 | AC127: 18514906 | AD127: 19201768 | AE127: 19901646 | AF127: 20616096 | AG127: 21356219 | AH127: 22118434 | AI127: 22892651 | AJ127: 23646514 | AK127: 24382460 | AL127: 25117188 | AM127: 25857130 | AN127: 26601751 | AO127: 27344211 | AP127: 28101768 | AQ127: 28888057 | AR127: 29733408 | AS127: 30642890 | AT127: 31619170 | AU127: 32629808 | AV127: 33652223 | AW127: 34713455 | AX127: 35796484 | AY127: 36904008 | AZ127: 38036349 | BA127: 39206351 | BB127: 40408891 | BC127: 41598567 | BD127: 42758461 | BE127: 43888303 | BF127: 44986791 | BG127: 46051440 | BH127: 47088526 | BI127: 48139687 | BJ127: 49197766 | BK127: 50207107 | BL127: 51202827 | BM127: 52217334 | BN127: 53219166 | BO127: 54252461 | BP127: 55339003 | BQ127: =BP127 -> 55339003 | BR127: =IF(ISERROR(INDEX(GDP!$A:$A, MATCH($A127, GDP!$A:$A, 0 ) )), "No", "Yes") -> Yes | BS127: =A127=GDP_WB_Data_202505!A127 -> TRUE
A128: Kyrgyzstan | B128: KGZ | C128: Population, total | D128: SP.POP.TOTL | E128: 2172300 | F128: 2255900 | G128: 2333400 | H128: 2413700 | I128: 2495300 | J128: 2573300 | K128: 2655300 | L128: 2736500 | M128: 2818300 | N128: 2894800 | O128: 2959900 | P128: 3022300 | Q128: 3088200 | R128: 3153800 | S128: 3223900 | T128: 3292400 | U128: 3358700 | V128: 3423900 | W128: 3487100 | X128: 3552000 | Y128: 3617400 | Z128: 3685800 | AA128: 3759300 | AB128: 3838300 | AC128: 3916400 | AD128: 3990300 | AE128: 4066500 | AF128: 4144600 | AG128: 4218400 | AH128: 4307500 | AI128: 4391236 | AJ128: 4463634 | AK128: 4515399.5 | AL128: 4516777 | AM128: 4515068.5 | AN128: 4560454 | AO128: 4628437.5 | AP128: 4696420.5 | AQ128: 4769014.5 | AR128: 4840422 | AS128: 4898361.5 | AT128: 4945072.5 | AU128: 4990704 | AV128: 5043308 | AW128: 5104712.5 | AX128: 5162639.5 | AY128: 5218373 | AZ128: 5268384.5 | BA128: 5318729 | BB128: 5389643 | BC128: 5467059 | BD128: 5546586.5 | BE128: 5652076 | BF128: 5777150 | BG128: 5905847.5 | BH128: 6040035.5 | BI128: 6175337.5 | BJ128: 6306695.5 | BK128: 6444078.5 | BL128: 6590211 | BM128: 6726595.5 | BN128: 6851224 | BO128: 6975219.5 | BP128: 7099750 | BQ128: =BP128 -> 7099750 | BR128: =IF(ISERROR(INDEX(GDP!$A:$A, MATCH($A128, GDP!$A:$A, 0 ) )), "No", "Yes") -> Yes | BS128: =A128=GDP_WB_Data_202505!A128 -> TRUE
... A201: Paraguay | B201: PRY | C201: Population, total | D201: SP.POP.TOTL | E201: 1883514 | F201: 1927394 | G201: 1973130 | H201: 2021909 | I201: 2073119 | J201: 2125177 | K201: 2177584 | L201: 2229994 | M201: 2282391 | N201: 2334992 | O201: 2388028 | P201: 2442537 | Q201: 2499881 | R201: 2561102 | S201: 2625621 | T201: 2691648 | U201: 2758836 | V201: 2827874 | W201: 2899269 | X201: 2973968 | Y201: 3053235 | Z201: 3137604 | AA201: 3226189 | AB201: 3318068 | AC201: 3412936 | AD201: 3510671 | AE201: 3611474 | AF201: 3714889 | AG201: 3820546 | AH201: 3927802 | AI201: 4035747 | AJ201: 4144364 | AK201: 4253600 | AL201: 4362696 | AM201: 4471417 | AN201: 4579806 | AO201: 4687543 | AP201: 4794412 | AQ201: 4900025 | AR201: 5003135 | AS201: 5100868 | AT201: 5187689 | AU201: 5261328 | AV201: 5326436 | AW201: 5388175 | AX201: 5448097 | AY201: 5505148 | AZ201: 5559386 | BA201: 5613574 | BB201: 5671236 | BC201: 5737971 | BD201: 5814626 | BE201: 5897008 | BF201: 5982445 | BG201: 6069811 | BH201: 6159103 | BI201: 6249126 | BJ201: 6338660 | BK201: 6427382 | BL201: 6515058 | BM201: 6603739 | BN201: 6684182 | BO201: 6760464 | BP201: 6844146 | BQ201: =BP201 -> 6844146 | BR201: =IF(ISERROR(INDEX(GDP!$A:$A, MATCH($A201, GDP!$A:$A, 0 ) )), "No", "Yes") -> No | BS201: =A201=GDP_WB_Data_202505!A201 -> TRUE
A202: West Bank and Gaza | B202: PSE | C202: Population, total | D202: SP.POP.TOTL | AI202: 1978248 | AJ202: 2068845 | AK202: 2163591 | AL202: 2262676 | AM202: 2366298 | AN202: 2474666 | AO202: 2587997 | AP202: 2706518 | AQ202: 2776568 | AR202: 2848431 | AS202: 2922153 | AT202: 2997784 | AU202: 3075373 | AV202: 3154969 | AW202: 3236626 | AX202: 3320396 | AY202: 3406334 | AZ202: 3494496 | BA202: 3591977 | BB202: 3689099 | BC202: 3786161 | BD202: 3882986 | BE202: 3979998 | BF202: 4076708 | BG202: 4173398 | BH202: 4270092 | BI202: 4367088 | BJ202: 4454805 | BK202: 4569087 | BL202: 4685306 | BM202: 4803269 | BN202: 4922749 | BO202: 5043612 | BP202: 5165775 | BQ202: =BP202 -> 5165775 | BR202: =IF(ISERROR(INDEX(GDP!$A:$A, MATCH($A202, GDP!$A:$A, 0 ) )), "No", "Yes") -> No | BS202: =A202=GDP_WB_Data_202505!A202 -> TRUE
A203: Pacific island small states | B203: PSS | C203: Population, total | D203: SP.POP.TOTL | E203: 912120 | F203: 938244 | G203: 965430 | H203: 993524 | I203: 1022081 | J203: 1051140 | K203: 1079689 | L203: 1105889 | M203: 1130851 | N203: 1156327 | O203: 1181537 | P203: 1205879 | Q203: 1229695 | R203: 1253169 | S203: 1277600 | T203: 1303608 | U203: 1331351 | V203: 1360619 | W203: 1390784 | X203: 1422234 | Y203: 1454476 | Z203: 1487561 | AA203: 1521261 | AB203: 1555284 | AC203: 1590058 | AD203: 1625654 | AE203: 1660533 | AF203: 1692234 | AG203: 1721206 | AH203: 1748900 | AI203: 1775607 | AJ203: 1801531 | AK203: 1827395 | AL203: 1853148 | AM203: 1878007 | AN203: 1901782 | AO203: 1926342 | AP203: 1954642 | AQ203: 1984859 | AR203: 2014289 | AS203: 2042274 | AT203: 2069097 | AU203: 2095273 | AV203: 2120592 | AW203: 2145505 | AX203: 2170029 | AY203: 2194265 | AZ203: 2218230 | BA203: 2240739 | BB203: 2262456 | BC203: 2289399 | BD203: 2320899 | BE203: 2351924 | BF203: 2382931 | BG203: 2414338 | BH203: 2445989 | BI203: 2477794 | BJ203: 2509999 | BK203: 2542009 | BL203: 2568656 | BM203: 2595522 | BN203: 2625493 | BO203: 2656049 | BP203: 2689224 | BQ203: =BP203 -> 2689224 | BR203: =IF(ISERROR(INDEX(GDP!$A:$A, MATCH($A203, GDP!$A:$A, 0 ) )), "No", "Yes") -> No | BS203: =A203=GDP_WB_Data_202505!A203 -> TRUE
A204: Post-demographic dividend | B204: PST | C204: Population, total | D204: SP.POP.TOTL | E204: 756379385 | F204: 765443499 | G204: 774679689 | H204: 783736508 | I204: 792735136 | J204: 801451274 | K204: 809623605 | L204: 817437528 | M204: 825029113 | N204: 832633761 | O204: 840190480 | P204: 849553629 | Q204: 857513072 | R204: 865015884 | S204: 872247955 | T204: 879088327 | U204: 885244462 | V204: 891301791 | W204: 897398355 | X204: 903773491 | Y204: 909919829 | Z204: 916024683 | AA204: 921558505 | AB204: 926768139 | AC204: 931624894 | AD204: 936480384 | AE204: 941566838 | AF204: 946817118 | AG204: 952284317 | AH204: 958176572 | AI204: 964371624 | AJ204: 971291914 | AK204: 978087877 | AL204: 984398082 | AM204: 990028770 | AN204: 995338472 | AO204: 1000836719 | AP204: 1006102041 | AQ204: 1011086034 | AR204: 1015990094 | AS204: 1021150563 | AT204: 1026102991 | AU204: 1031271721 | AV204: 1036412650 | AW204: 1041747900 | AX204: 1046942910 | AY204: 1052610469 | AZ204: 1058829365 | BA204: 1065219261 | BB204: 1070658067 | BC204: 1075615574 | BD204: 1078564678 | BE204: 1083068159 | BF204: 1087808342 | BG204: 1092805112 | BH204: 1097599410 | BI204: 1102507839 | BJ204: 1106644744 | BK204: 1110512190 | BL204: 1113651656 | BM204: 1117765361 | BN204: 1117015201 | BO204: 1117561802 | BP204: 1119236161 | BQ204: =BP204 -> 1119236161 | BR204: =IF(ISERROR(INDEX(GDP!$A:$A, MATCH($A204, GDP!$A:$A, 0 ) )), "No", "Yes") -> No | BS204: =A204=GDP_WB_Data_202505!A204 -> TRUE
A205: French Polynesia | B205: PYF | C205: Population, total | D205: SP.POP.TOTL | E205: 83671 | F205: 85434 | G205: 87261 | H205: 89737 | I205: 92823 | J205: 96017 | K205: 99320 | L205: 102754 | M205: 106353 | N205: 110111 | O205: 114010 | P205: 117945 | Q205: 121886 | R205: 125897 | S205: 129960 | T205: 134045 | U205: 138114 | V205: 142313 | W205: 146821 | X205: 151569 | Y205: 156471 | Z205: 161506 | AA205: 166646 | AB205: 171750 | AC205: 176469 | AD205: 180988 | AE205: 185669 | AF205: 190449 | AG205: 195193 | AH205: 199643 | AI205: 203776 | AJ205: 207744 | AK205: 211559 | AL205: 215219 | AM205: 218738 | AN205: 222118 | AO205: 225489 | AP205: 229121 | AQ205: 232891 | AR205: 236595 | AS205: 240337 | AT205: 244097 | AU205: 247775 | AV205: 251637 | AW205: 255654 | AX205: 259507 | AY205: 263223 | AZ205: 266438 | BA205: 268379 | BB205: 269481 | BC205: 270580 | BD205: 271727 | BE205: 273084 | BF205: 274728 | BG205: 276387 | BH205: 277866 | BI205: 279178 | BJ205: 280087 | BK205: 279815 | BL205: 279034 | BM205: 279209 | BN205: 279792 | BO205: 280378 | BP205: 281118 | BQ205: =BP205 -> 281118 | BR205: =IF(ISERROR(INDEX(GDP!$A:$A, MATCH($A205, GDP!$A:$A, 0 ) )), "No", "Yes") -> No | BS205: =A205=GDP_WB_Data_202505!A205 -> TRUE
A206: Qatar | B206: QAT | C206: Population, total | D206: SP.POP.TOTL | E206: 36010 | F206: 39680 | G206: 44630 | H206: 50380 | I206: 56867 | J206: 64065 | K206: 72192 | L206: 81439 | M206: 91749 | N206: 103025 | O206: 116350 | P206: 131346 | Q206: 146506 | R206: 161841 | S206: 177362 | T206: 193087 | U206: 209052 | V206: 225285 | W206: 241808 | X206: 258670 | Y206: 275913 | Z206: 293553 | AA206: 311537 | AB206: 329709 | AC206: 347878 | AD206: 365940 | AE206: 382422 | AF206: 397005 | AG206: 411264 | AH206: 425646 | AI206: 440175 | AJ206: 454853 | AK206: 469657 | AL206: 484545 | AM206: 499459 | AN206: 514325 | AO206: 529019 | AP206: 550500 | AQ206: 580540 | AR206: 612500 | AS206: 644989 | AT206: 677925 | AU206: 711205 | AV206: 744682 | AW206: 773332 | AX206: 825408 | AY206: 972831 | AZ206: 1208595 | BA206: 1426938 | BB206: 1608903 | BC206: 1616832 | BD206: 1624761 | BE206: 1722438 | BF206: 1916426 | BG206: 2151745 | BH206: 2344557 | BI206: 2477113 | BJ206: 2545820 | BK206: 2580734 | BL206: 2638657 | BM206: 2794148 | BN206: 2504910 | BO206: 2657333 | BP206: 2656032 | BQ206: =BP206 -> 2656032 | BR206: =IF(ISERROR(INDEX(GDP!$A:$A, MATCH($A206, GDP!$A:$A, 0 ) )), "No", "Yes") -> No | BS206: =A206=GDP_WB_Data_202505!A206 -> TRUE
A207: Romania | B207: ROU | C207: Population, total | D207: SP.POP.TOTL | E207: 18406905 | F207: 18555250 | G207: 18676550 | H207: 18797850 | I207: 18919126 | J207: 19031576 | K207: 19215450 | L207: 19534242 | M207: 19799831 | N207: 20009141 | O207: 20250398 | P207: 20461567 | Q207: 20657957 | R207: 20835681 | S207: 21029429 | T207: 21293583 | U207: 21551634 | V207: 21756096 | W207: 21951464 | X207: 22090488 | Y207: 22207282 | Z207: 22353070 | AA207: 22475741 | AB207: 22560478 | AC207: 22640547 | AD207: 22732999 | AE207: 22836841 | AF207: 22949430 | AG207: 23057662 | AH207: 23161458 | AI207: 23201835 | AJ207: 23001155 | AK207: 22794284 | AL207: 22763280 | AM207: 22730211 | AN207: 22684270 | AO207: 22619004 | AP207: 22553978 | AQ207: 22507344 | AR207: 22472040 | AS207: 22442971 | AT207: 22131970 | AU207: 21730496 | AV207: 21574326 | AW207: 21451748 | AX207: 21319685 | AY207: 21193760 | AZ207: 20882982 | BA207: 20537875 | BB207: 20367487 | BC207: 20246871 | BD207: 20147528 | BE207: 20058035 | BF207: 19983693 | BG207: 19908979 | BH207: 19815616 | BI207: 19702267 | BJ207: 19588715 | BK207: 19473970 | BL207: 19371648 | BM207: 19265250 | BN207: 19122059 | BO207: 19048502 | BP207: 19059479 | BQ207: =BP207 -> 19059479 | BR207: =IF(ISERROR(INDEX(GDP!$A:$A, MATCH($A207, GDP!$A:$A, 0 ) )), "No", "Yes") -> Yes | BS207: =A207=GDP_WB_Data_202505!A207 -> TRUE
A208: Russian Federation | B208: RUS | C208: Population, total | D208: SP.POP.TOTL | E208: 119897000 | F208: 121236000 | G208: 122591000 | H208: 123960000 | I208: 125345000 | J208: 126745000 | K208: 127468000 | L208: 128196000 | M208: 128928000 | N208: 129664000 | O208: 130404000 | P208: 131155000 | Q208: 131909000 | R208: 132669000 | S208: 133432000 | T208: 134200000 | U208: 135147000 | V208: 136100000 | W208: 137060000 | X208: 138027000 | Y208: 139010000 | Z208: 139941000 | AA208: 140823000 | AB208: 141668000 | AC208: 142745000 | AD208: 143858000 | AE208: 144894000 | AF208: 145908000 | AG208: 146857000 | AH208: 147721000 | AI208: 147969406 | AJ208: 148394216 | AK208: 148538197 | AL208: 148458777 | AM208: 148407912 | AN208: 148375787 | AO208: 148160129 | AP208: 147915361 | AQ208: 147670784 | AR208: 147214776 | AS208: 146596869 | AT208: 145976482 | AU208: 145306497 | AV208: 144648618 | AW208: 144067316 | AX208: 143518814 | AY208: 143049637 | AZ208: 142805114 | BA208: 142742366 | BB208: 142785348 | BC208: 142849468 | BD208: 143018195 | BE208: 143378447 | BF208: 143805638 | BG208: 144237223 | BH208: 144640716 | BI208: 145015460 | BJ208: 145293260 | BK208: 145398106 | BL208: 145453291 | BM208: 145245148 | BN208: 144746762 | BO208: 144236933 | BP208: 143826130 | BQ208: =BP208 -> 143826130 | BR208: =IF(ISERROR(INDEX(GDP!$A:$A, MATCH($A208, GDP!$A:$A, 0 ) )), "No", "Yes") -> No | BS208: =A208=GDP_WB_Data_202505!A208 -> TRUE
A209: Rwanda | B209: RWA | C209: Population, total | D209: SP.POP.TOTL | E209: 3022294 | F209: 3106779 | G209: 3186025 | H209: 3258890 | I209: 3334834 | J209: 3423210 | K209: 3521626 | L209: 3629577 | M209: 3744010 | N209: 3861271 | O209: 3980669 | P209: 4100044 | Q209: 4220335 | R209: 4345047 | S209: 4474228 | T209: 4607728 | U209: 4745954 | V209: 4888240 | W209: 5035171 | X209: 5189541 | Y209: 5353259 | Z209: 5527230 | AA209: 5711549 | AB209: 5905311 | AC209: 6107627 | AD209: 6317228 | AE209: 6531881 | AF209: 6749493 | AG209: 6968071 | AH209: 7184706 | AI209: 7375307 | AJ209: 7526966 | AK209: 7683266 | AL209: 7981132 | AM209: 6792352 | AN209: 5674118 | AO209: 6708764 | AP209: 7755238 | AQ209: 8081681 | AR209: 8147912 | AS209: 8213931 | AT209: 8287094 | AU209: 8400180 | AV209: 8586875 | AW209: 8816844 | AX209: 9054528 | AY209: 9299246 | AZ209: 9549933 | BA209: 9804269 | BB209: 10060432 | BC209: 10317553 | BD209: 10573733 | BE209: 10829901 | BF209: 11093340 | BG209: 11364757 | BH209: 11640022 | BI209: 11919183 | BJ209: 12202060 | BK209: 12487996 | BL209: 12776103 | BM209: 13065837 | BN209: 13355260 | BO209: 13651030 | BP209: 13954471 | BQ209: =BP209 -> 13954471 | BR209: =IF(ISERROR(INDEX(GDP!$A:$A, MATCH($A209, GDP!$A:$A, 0 ) )), "No", "Yes") -> No | BS209: =A209=GDP_WB_Data_202505!A209 -> TRUE
A210: South Asia | B210: SAS | C210: Population, total | D210: SP.POP.TOTL | E210: 562663671 | F210: 576552257 | G210: 590723078 | H210: 605163476 | I210: 619975727 | J210: 634743361 | K210: 649326080 | L210: 664339452 | M210: 679739334 | N210: 695251697 | O210: 711535056 | P210: 727496928 | Q210: 743820087 | R210: 761620615 | S210: 780131997 | T210: 799327643 | U210: 818897740 | V210: 839003065 | W210: 859247929 | X210: 880093189 | Y210: 901830096 | Z210: 923378190 | AA210: 945429976 | AB210: 968588030 | AC210: 992249656 | AD210: 1016278162 | AE210: 1040673027 | AF210: 1065320678 | AG210: 1090292188 | AH210: 1115781733 | AI210: 1141498254 | AJ210: 1167357434 | AK210: 1193900392 | AL210: 1221219670 | AM210: 1248304394 | AN210: 1275163648 | AO210: 1302319006 | AP210: 1329609793 | AQ210: 1357088282 | AR210: 1384716971 | AS210: 1412194936 | AT210: 1439704270 | AU210: 1467185462 | AV210: 1494191087 | AW210: 1520797241 | AX210: 1546744163 | AY210: 1572294133 | AZ210: 1597352539 | BA210: 1622028899 | BB210: 1647212835 | BC210: 1672490146 | BD210: 1697466396 | BE210: 1721780232 | BF210: 1744358673 | BG210: 1766896416 | BH210: 1788492725 | BI210: 1809951345 | BJ210: 1831474329 | BK210: 1852836645 | BL210: 1874070006 | BM210: 1895144142 | BN210: 1914263569 | BO210: 1932289074 | BP210: 1951539835 | BQ210: =BP210 -> 1951539835 | BR210: =IF(ISERROR(INDEX(GDP!$A:$A, MATCH($A210, GDP!$A:$A, 0 ) )), "No", "Yes") -> No | BS210: =A210=GDP_WB_Data_202505!A210 -> TRUE
A211: Saudi Arabia | B211: SAU | C211: Population, total | D211: SP.POP.TOTL | E211: 2435403 | F211: 2526347 | G211: 2620910 | H211: 2719341 | I211: 2821968 | J211: 2928771 | K211: 3039887 | L211: 3157242 | M211: 3282711 | N211: 3417114 | O211: 3562470 | P211: 3724031 | Q211: 3905722 | R211: 4106344 | S211: 4323632 | T211: 4556287 | U211: 4807933 | V211: 5083048 | W211: 5381902 | X211: 5703698 | Y211: 6047997 | Z211: 6420551 | AA211: 6824486 | AB211: 7252941 | AC211: 7697307 | AD211: 8151779 | AE211: 8628639 | AF211: 9130194 | AG211: 9629165 | AH211: 10128394 | AI211: 10640691 | AJ211: 11160744 | AK211: 11686676 | AL211: 12215862 | AM211: 12750040 | AN211: 13289245 | AO211: 13831009 | AP211: 14374943 | AQ211: 14922185 | AR211: 15472075 | AS211: 16177722 | AT211: 17041397 | AU211: 17910910 | AV211: 18786767 | AW211: 19669480 | AX211: 20559890 | AY211: 21459144 | AZ211: 22368313 | BA211: 23287877 | BB211: 24217654 | BC211: 23978487 | BD211: 25091867 | BE211: 26168861 | BF211: 27624004 | BG211: 28309273 | BH211: 29816382 | BI211: 30954198 | BJ211: 30977355 | BK211: 30196281 | BL211: 30063799 | BM211: 31552510 | BN211: 30784383 | BO211: 32175224 | BP211: 33264292 | BQ211: =BP211 -> 33264292 | BR211: =IF(ISERROR(INDEX(GDP!$A:$A, MATCH($A211, GDP!$A:$A, 0 ) )), "No", "Yes") -> No | BS211: =A211=GDP_WB_Data_202505!A211 -> TRUE
A212: Sudan | B212: SDN | C212: Population, total | D212: SP.POP.TOTL | E212: 8364489 | F212: 8634941 | G212: 8919028 | H212: 9218077 | I212: 9531109 | J212: 9858030 | K212: 10197578 | L212: 10550597 | M212: 10917999 | N212: 11298936 | O212: 11695771 | P212: 12105539 | Q212: 12527856 | R212: 13049315 | S212: 13580723 | T212: 14064798 | U212: 14569716 | V212: 15086614 | W212: 15695003 | X212: 16355352 | Y212: 17058905 | Z212: 17780572 | AA212: 18486645 | AB212: 19109770 | AC212: 19546528 | AD212: 19905872 | AE212: 20288238 | AF212: 20704904 | AG212: 21138431 | AH212: 21578022 | AI212: 22021481 | AJ212: 22470676 | AK212: 22927355 | AL212: 23445592 | AM212: 24043948 | AN212: 24672143 | AO212: 25231528 | AP212: 25799821 | AQ212: 26458999 | AR212: 27130613 | AS212: 27816745 | AT212: 28516770 | AU212: 29228727 | AV212: 29896035 | AW212: 30556637 | AX212: 31262444 | AY212: 31992435 | AZ212: 32764135 | BA212: 33623980 | BB212: 34569113 | BC212: 35414399 | BD212: 36140806 | BE212: 36923178 | BF212: 37785849 | BG212: 38823318 | BH212: 40024431 | BI212: 41259892 | BJ212: 42714306 | BK212: 44230596 | BL212: 45548175 | BM212: 46789231 | BN212: 48066924 | BO212: 49383346 | BP212: 50042791 | BQ212: =BP212 -> 50042791 | BR212: =IF(ISERROR(INDEX(GDP!$A:$A, MATCH($A212, GDP!$A:$A, 0 ) )), "No", "Yes") -> No | BS212: =A212=GDP_WB_Data_202505!A212 -> TRUE
A213: Senegal | B213: SEN | C213: Population, total | D213: SP.POP.TOTL | E213: 3340907 | F213: 3436375 | G213: 3534686 | H213: 3635876 | I213: 3740535 | J213: 3849788 | K213: 3964299 | L213: 4083870 | M213: 4207587 | N213: 4334974 | O213: 4466328 | P213: 4601864 | Q213: 4741631 | R213: 4885181 | S213: 5029437 | T213: 5170810 | U213: 5308564 | V213: 5439549 | W213: 5568096 | X213: 5702895 | Y213: 5845638 | Z213: 5997160 | AA213: 6156961 | AB213: 6324504 | AC213: 6499364 | AD213: 6683287 | AE213: 6878192 | AF213: 7081530 | AG213: 7289618 | AH213: 7502207 | AI213: 7720523 | AJ213: 7943085 | AK213: 8168395 | AL213: 8396288 | AM213: 8624078 | AN213: 8848101 | AO213: 9067014 | AP213: 9283495 | AQ213: 9502952 | AR213: 9730887 | AS213: 9968260 | AT213: 10212942 | AU213: 10466214 | AV213: 10721176 | AW213: 10975704 | AX213: 11235472 | AY213: 11500094 | AZ213: 11770344 | BA213: 12048959 | BB213: 12337389 | BC213: 12635413 | BD213: 12958897 | BE213: 13310495 | BF213: 13710849 | BG213: 14152102 | BH213: 14593331 | BI213: 15034521 | BJ213: 15475002 | BK213: 15914498 | BL213: 16352922 | BM213: 16789219 | BN213: 17220867 | BO213: 17651103 | BP213: 18077573 | BQ213: =BP213 -> 18077573 | BR213: =IF(ISERROR(INDEX(GDP!$A:$A, MATCH($A213, GDP!$A:$A, 0 ) )), "No", "Yes") -> No | BS213: =A213=GDP_WB_Data_202505!A213 -> TRUE
...

Sheet GDP_WB_Data_202505
A1: Data Source | B1: World Development Indicators
A3: Last Updated Date | B3: 45762
A5: Country Name | B5: Country Code | C5: Indicator Name | D5: Indicator Code | E5: 1960 | F5: 1961 | G5: 1962 | H5: 1963 | I5: 1964 | J5: 1965 | K5: 1966 | L5: 1967 | M5: 1968 | N5: 1969 | O5: 1970 | P5: 1971 | Q5: 1972 | R5: 1973 | S5: 1974 | T5: 1975 | U5: 1976 | V5: 1977 | W5: 1978 | X5: 1979 | Y5: 1980 | Z5: 1981 | AA5: 1982 | AB5: 1983 | AC5: 1984 | AD5: 1985 | AE5: 1986 | AF5: 1987 | AG5: 1988 | AH5: 1989 | AI5: 1990 | AJ5: 1991 | AK5: 1992 | AL5: 1993 | AM5: 1994 | AN5: 1995 | AO5: 1996 | AP5: 1997 | AQ5: 1998 | AR5: 1999 | AS5: 2000 | AT5: 2001 | AU5: 2002 | AV5: 2003 | AW5: 2004 | AX5: 2005 | AY5: 2006 | AZ5: 2007 | BA5: 2008 | BB5: 2009 | BC5: 2010 | BD5: 2011 | BE5: 2012 | BF5: 2013 | BG5: 2014 | BH5: 2015 | BI5: 2016 | BJ5: 2017 | BK5: 2018 | BL5: 2019 | BM5: 2020 | BN5: 2021 | BO5: 2022 | BP5: 2023 | BQ5: 2024 | BR5: Included
A6: Aruba | B6: ABW | C6: GDP (current US$) | D6: NY.GDP.MKTP.CD | AE6: 4.0558659e+08 | AF6: 4.877095e+08 | AG6: 5.9664804e+08 | AH6: 6.9553073e+08 | AI6: 7.6480447e+08 | AJ6: 8.7206704e+08 | AK6: 9.5865922e+08 | AL6: 1.0832402e+09 | AM6: 1.2458101e+09 | AN6: 1.3206704e+09 | AO6: 1.3798883e+09 | AP6: 1.5318436e+09 | AQ6: 1.6653631e+09 | AR6: 1.722905e+09 | AS6: 1.8734525e+09 | AT6: 1.896457e+09 | AU6: 1.9618436e+09 | AV6: 2.0441117e+09 | AW6: 2.2548307e+09 | AX6: 2.3600173e+09 | AY6: 2.4697827e+09 | AZ6: 2.6776413e+09 | BA6: 2.8430246e+09 | BB6: 2.5537933e+09 | BC6: 2.4535972e+09 | BD6: 2.6378592e+09 | BE6: 2.6152084e+09 | BF6: 2.7278497e+09 | BG6: 2.7908497e+09 | BH6: 2.9629073e+09 | BI6: 2.9836352e+09 | BJ6: 3.0924291e+09 | BK6: 3.2761844e+09 | BL6: 3.3957989e+09 | BM6: 2.4818571e+09 | BN6: 2.9294466e+09 | BO6: 3.2793435e+09 | BP6: 3.6485731e+09 | BQ6: =BP6 -> 3.6485731e+09 | BR6: =IF(ISERROR(INDEX(GDP!$A:$A, MATCH($A6, GDP!$A:$A, 0 ) )), "No", "Yes") -> No
A7: Africa Eastern and Southern | B7: AFE | C7: GDP (current US$) | D7: NY.GDP.MKTP.CD | E7: 2.4210633e+10 | F7: 2.4963978e+10 | G7: 2.7078797e+10 | H7: 3.1775749e+10 | I7: 3.0285794e+10 | J7: 3.3813171e+10 | K7: 3.6934975e+10 | L7: 3.8452171e+10 | M7: 4.1750717e+10 | N7: 4.7058301e+10 | O7: 4.7603734e+10 | P7: 5.2199396e+10 | Q7: 5.6737525e+10 | R7: 7.3098452e+10 | S7: 8.9554214e+10 | T7: 9.5315091e+10 | U7: 9.6025946e+10 | V7: 1.0923077e+11 | W7: 1.2410935e+11 | X7: 1.4212955e+11 | Y7: 1.7850936e+11 | Z7: 1.8516315e+11 | AA7: 1.784051e+11 | AB7: 1.8582257e+11 | AC7: 1.7010008e+11 | AD7: 1.4939817e+11 | AE7: 1.606377e+11 | AF7: 1.9027454e+11 | AG7: 2.0747033e+11 | AH7: 2.2071247e+11 | AI7: 2.5651231e+11 | AJ7: 2.7649366e+11 | AK7: 2.4127631e+11 | AL7: 2.4009633e+11 | AM7: 2.4357115e+11 | AN7: 2.7343318e+11 | AO7: 2.7353101e+11 | AP7: 2.8837767e+11 | AQ7: 2.6883348e+11 | AR7: 2.6542929e+11 | AS7: 2.8720165e+11 | AT7: 2.6099223e+11 | AU7: 2.6781504e+11 | AV7: 3.5571637e+11 | AW7: 4.4269619e+11 | AX7: 5.1666107e+11 | AY7: 5.8024075e+11 | AZ7: 6.655987e+11 | BA7: 7.1350211e+11 | BB7: 7.1548533e+11 | BC7: 8.4940966e+11 | BD7: 9.4543915e+11 | BE7: 9.5299856e+11 | BF7: 9.6239492e+11 | BG7: 9.7870826e+11 | BH7: 8.9827781e+11 | BI7: 8.2894281e+11 | BJ7: 9.7299893e+11 | BK7: 1.012306e+12 | BL7: 1.0097212e+12 | BM7: 9.3339178e+11 | BN7: 1.0857452e+12 | BO7: 1.1914232e+12 | BP7: 1.2454725e+12 | BQ7: =BP7 -> 1.2454725e+12 | BR7: =IF(ISERROR(INDEX(GDP!$A:$A, MATCH($A7, GDP!$A:$A, 0 ) )), "No", "Yes") -> No
A8: Afghanistan | B8: AFG | C8: GDP (current US$) | D8: NY.GDP.MKTP.CD | AS8: 3.5214181e+09 | AT8: 2.8135718e+09 | AU8: 3.8257014e+09 | AV8: 4.5209468e+09 | AW8: 5.2248967e+09 | AX8: 6.2032565e+09 | AY8: 6.9717583e+09 | AZ8: 9.7478862e+09 | BA8: 1.0109297e+10 | BB8: 1.2416153e+10 | BC8: 1.5856669e+10 | BD8: 1.7805098e+10 | BE8: 1.990733e+10 | BF8: 2.0146417e+10 | BG8: 2.0497129e+10 | BH8: 1.9134222e+10 | BI8: 1.8116572e+10 | BJ8: 1.8753456e+10 | BK8: 1.8053223e+10 | BL8: 1.8799444e+10 | BM8: 1.9955929e+10 | BN8: 1.4259995e+10 | BO8: 1.4497244e+10 | BP8: 1.7233052e+10 | BQ8: =BP8 -> 1.7233052e+10 | BR8: =IF(ISERROR(INDEX(GDP!$A:$A, MATCH($A8, GDP!$A:$A, 0 ) )), "No", "Yes") -> Yes
